<?xml version="1.0" ?>
<robot xmlns:xacro="http://www.ros.org/wiki/xacro" name="swarm_farm">
  <xacro:include filename="$(find krytn)/robot_description/magni/inertial.xacro" />

  <!--Generated by CROSS, a ROS Workbench for FreeCAD (https://github.com/galou/freecad.cross)-->
  <link name="front_chassis_link">
    <visual>
      <!--front_chassis_part/Body.-->
      <origin rpy="0.0 -0.0 0.0" xyz="0.0 0.0 0.0"/>
      <geometry>
        <mesh filename="file://$(find sprayerbot)/robot_description/meshes/swarmfarmv2_front_chassis_body.dae"/>
      </geometry>
    </visual>
    <!-- 
    <collision>
      <origin rpy="0.0 -0.0 0.0" xyz="0.0 0.0 0.0"/>
      <geometry>
        <mesh filename="file://$(find sprayerbot)/robot_description/meshes/swarmfarmv2_front_chassis_body.dae"/>
      </geometry>
    </collision>
    -->

    <xacro:box_inertial x="1" y="1" z="1" mass="20" />

  </link>

  <link name="back_chassis_link">
    <visual>
      <!--back_chassis_part/Body001.-->
      <origin rpy="0.0 -0.0 0.0" xyz="0.0 0.0 0.0"/>
      <geometry>
        <mesh filename="file://$(find sprayerbot)/robot_description/meshes/swarmfarmv2_back_chassis_body.dae"/>
      </geometry>
    </visual>
    <visual>
      <!--back_chassis_part/Body003.-->
      <origin rpy="0.0 -0.0 0.0" xyz="0.0 0.0 0.0"/>
      <geometry>
        <mesh filename="file://$(find sprayerbot)/robot_description/meshes/swarmfarmv2_spray_liquid.dae"/>
      </geometry>
    </visual>
    <visual>
      <!--back_chassis_part/Body004.-->
      <origin rpy="0.0 -0.0 0.0" xyz="0.0 0.0 0.0"/>
      <geometry>
        <mesh filename="file://$(find sprayerbot)/robot_description/meshes/swarmfarmv2_spray_boom.dae"/>
      </geometry>
    </visual>


    <xacro:box_inertial x="1" y="1" z="1" mass="20" />
  </link>


  <xacro:macro name="wheel" params="prefix rotation">
    <link name="${prefix}_wheel_link">
      <visual>
        <!--wheel_part/Body002.-->
        <origin rpy="0.0 -0.0 ${rotation}" xyz="0.0 0.0 0.0"/>
        <geometry>
          <mesh filename="file://$(find sprayerbot)/robot_description/meshes/swarmfarmv2_wheel_body.dae"/>
        </geometry>
      </visual>
      <collision>
        <!--wheel_part/Body002.-->
        <origin rpy="${pi/2} -0.0 0.0" xyz="0.0 0.0 0.0"/>
        <geometry>
          <cylinder radius="0.3" length="0.3" />
        </geometry>
      </collision>
      <xacro:cylinder_inertial radius="0.3" length="0.3" mass="10" />
    </link>
  </xacro:macro>

  <xacro:wheel prefix="front_right" rotation="3.14" />
  <xacro:wheel prefix="front_left" rotation="0.0" />
  <xacro:wheel prefix="back_right" rotation="3.14" />
  <xacro:wheel prefix="back_left" rotation="0.0" />

  <joint name="chassis_joint" type="revolute">
    <parent link="front_chassis_link"/>
    <child link="back_chassis_link"/>
    <origin rpy="0.0 -0.0 0.0" xyz="-1.2 0.0 0.0"/>
    <axis xyz="0 0 1"/>
    <limit effort="10.0" lower="-0.7" upper="+0.7" velocity="10.0"/>
  </joint>

  <xacro:macro name="wheel_joint" params="front_rear_pos left_right_pos *origin">

    <joint name="${front_rear_pos}_${left_right_pos}_wheel_joint" type="continuous">
      <parent link="${front_rear_pos}_chassis_link"/>
      <child link="${front_rear_pos}_${left_right_pos}_wheel_link"/>
      <xacro:insert_block name="origin" />
      <axis xyz="0 1 0"/>
    </joint>

  </xacro:macro>

  <xacro:wheel_joint front_rear_pos="front" left_right_pos="right">
    <origin rpy="0.0 -0.0 0.0" xyz="-0.3 -0.5 0.0"/>
  </xacro:wheel_joint>

  <xacro:wheel_joint front_rear_pos="front" left_right_pos="left">
    <origin rpy="0.0 -0.0 0.0" xyz="-0.3 0.5 0.0"/>
  </xacro:wheel_joint>

  <xacro:wheel_joint front_rear_pos="back" left_right_pos="right">
    <origin rpy="0.0 -0.0 0.0" xyz="-1.0 -0.5 0.0"/>
  </xacro:wheel_joint>

  <xacro:wheel_joint front_rear_pos="back" left_right_pos="left">
    <origin rpy="0.0 -0.0 0.0" xyz="-1.0 0.5 0.0"/>
  </xacro:wheel_joint>

  <ros2_control name="sprayer" type="system">
    <hardware>
      <plugin>ign_ros2_control/IgnitionSystem</plugin>
    </hardware>

    <joint name="front_left_wheel_joint">
      <command_interface name="velocity">
        <param name="min">-10</param>
        <param name="max">10</param>
      </command_interface>
      <state_interface name="position"/>
      <state_interface name="velocity"/>
      <state_interface name="effort" />
    </joint>

    <joint name="front_right_wheel_joint">
      <command_interface name="velocity">
        <param name="min">-10</param>
        <param name="max">10</param>
      </command_interface>

      <state_interface name="position"/>
      <state_interface name="velocity"/>
      <state_interface name="effort" />
    </joint>
  </ros2_control>


  <gazebo>
    <plugin filename="gz_ros2_control-system" name="gz_ros2_control::GazeboSimROS2ControlPlugin">
      <ros>
        <remapping>diff_drive_base_controller/odometry:=odom</remapping>
        <remapping>diff_drive_base_controller/tf_odometry:=tf</remapping>
        <remapping>diff_drive_base_controller/cmd_vel_unstamped:=cmd_vel</remapping>
        <remapping>/controller_manager/robot_description:=/robot_description</remapping>
      </ros>
      <parameters>$(find sprayerbot)/config/diffdrive_control.yaml</parameters>
    </plugin>


  </gazebo>

</robot>
