<?xml version="1.0" ?>
<robot name="swarm_farm">
  <!--Generated by CROSS, a ROS Workbench for FreeCAD (https://github.com/galou/freecad.cross)-->
  <link name="front_chassis_link">
    <visual>
      <!--front_chassis_part/Body.-->
      <origin rpy="0.0 -0.0 0.0" xyz="0.0 0.0 0.0"/>
      <geometry>
        <mesh filename="package://swarmfarm/meshes/swarmfarmv2_front_chassis_body.dae"/>
      </geometry>
    </visual>
    <collision>
      <!--front_chassis_part/Body.-->
      <origin rpy="0.0 -0.0 0.0" xyz="0.0 0.0 0.0"/>
      <geometry>
        <mesh filename="package://swarmfarm/meshes/swarmfarmv2_front_chassis_body.dae"/>
      </geometry>
    </collision>
    <inertial>
      <mass value="0.0"/>
      <origin rpy="0.0 -0.0 0.0" xyz="0.0 0.0 0.0"/>
      <inertia ixx="0.0" ixy="0.0" ixz="0.0" iyy="0.0" iyz="0.0" izz="0.0"/>
    </inertial>
  </link>
  <link name="back_chassis_link">
    <visual>
      <!--back_chassis_part/Body001.-->
      <origin rpy="0.0 -0.0 0.0" xyz="0.0 0.0 0.0"/>
      <geometry>
        <mesh filename="package://swarmfarm/meshes/swarmfarmv2_back_chassis_body.dae"/>
      </geometry>
    </visual>
    <visual>
      <!--back_chassis_part/Body003.-->
      <origin rpy="0.0 -0.0 0.0" xyz="0.0 0.0 0.0"/>
      <geometry>
        <mesh filename="package://swarmfarm/meshes/swarmfarmv2_spray_liquid.dae"/>
      </geometry>
    </visual>
    <visual>
      <!--back_chassis_part/Body004.-->
      <origin rpy="0.0 -0.0 0.0" xyz="0.0 0.0 0.0"/>
      <geometry>
        <mesh filename="package://swarmfarm/meshes/swarmfarmv2_spray_boom.dae"/>
      </geometry>
    </visual>
    <visual>
      <!--back_chassis_part/Body005.-->
      <origin rpy="0.0 -0.0 0.0" xyz="0.0 0.0 0.0"/>
      <geometry>
        <mesh filename="package://swarmfarm/meshes/swarmfarmv2_Body.dae"/>
      </geometry>
    </visual>
    <collision>
      <!--back_chassis_part/Body001.-->
      <origin rpy="0.0 -0.0 0.0" xyz="0.0 0.0 0.0"/>
      <geometry>
        <mesh filename="package://swarmfarm/meshes/swarmfarmv2_back_chassis_body.dae"/>
      </geometry>
    </collision>
    <collision>
      <!--back_chassis_part/Body003.-->
      <origin rpy="0.0 -0.0 0.0" xyz="0.0 0.0 0.0"/>
      <geometry>
        <mesh filename="package://swarmfarm/meshes/swarmfarmv2_spray_liquid.dae"/>
      </geometry>
    </collision>
    <collision>
      <!--back_chassis_part/Body004.-->
      <origin rpy="0.0 -0.0 0.0" xyz="0.0 0.0 0.0"/>
      <geometry>
        <mesh filename="package://swarmfarm/meshes/swarmfarmv2_spray_boom.dae"/>
      </geometry>
    </collision>
    <collision>
      <!--back_chassis_part/Body005.-->
      <origin rpy="0.0 -0.0 0.0" xyz="0.0 0.0 0.0"/>
      <geometry>
        <mesh filename="package://swarmfarm/meshes/swarmfarmv2_Body.dae"/>
      </geometry>
    </collision>
    <inertial>
      <mass value="0.0"/>
      <origin rpy="0.0 -0.0 0.0" xyz="0.0 0.0 0.0"/>
      <inertia ixx="0.0" ixy="0.0" ixz="0.0" iyy="0.0" iyz="0.0" izz="0.0"/>
    </inertial>
  </link>
  <link name="front_right_wheel_link">
    <visual>
      <!--wheel_part/Body002.-->
      <origin rpy="0.0 -0.0 3.14" xyz="0.0 0.0 0.0"/>
      <geometry>
        <mesh filename="package://swarmfarm/meshes/swarmfarmv2_wheel_body.dae"/>
      </geometry>
    </visual>
    <collision>
      <!--wheel_part/Body002.-->
      <origin rpy="0.0 -0.0 0.0" xyz="0.0 0.0 0.0"/>
      <geometry>
        <mesh filename="package://swarmfarm/meshes/swarmfarmv2_wheel_body.dae"/>
      </geometry>
    </collision>
    <inertial>
      <mass value="0.0"/>
      <origin rpy="0.0 -0.0 0.0" xyz="0.0 0.0 0.0"/>
      <inertia ixx="0.0" ixy="0.0" ixz="0.0" iyy="0.0" iyz="0.0" izz="0.0"/>
    </inertial>
  </link>
  <link name="front_left_wheel_link">
    <visual>
      <!--wheel_part/Body002.-->
      <origin rpy="0.0 -0.0 0" xyz="0.0 0.0 0.0"/>
      <geometry>
        <mesh filename="package://swarmfarm/meshes/swarmfarmv2_wheel_body.dae"/>
      </geometry>
    </visual>
    <collision>
      <!--wheel_part/Body002.-->
      <origin rpy="0.0 -0.0 0.0" xyz="0.0 0.0 0.0"/>
      <geometry>
        <mesh filename="package://swarmfarm/meshes/swarmfarmv2_wheel_body.dae"/>
      </geometry>
    </collision>
    <inertial>
      <mass value="0.0"/>
      <origin rpy="0.0 -0.0 0.0" xyz="0.0 0.0 0.0"/>
      <inertia ixx="0.0" ixy="0.0" ixz="0.0" iyy="0.0" iyz="0.0" izz="0.0"/>
    </inertial>
  </link>
  <link name="back_right_wheel_link">
    <visual>
      <!--wheel_part/Body002.-->
      <origin rpy="0.0 -0.0 3.14" xyz="0.0 0.0 0.0"/>
      <geometry>
        <mesh filename="package://swarmfarm/meshes/swarmfarmv2_wheel_body.dae"/>
      </geometry>
    </visual>
    <collision>
      <!--wheel_part/Body002.-->
      <origin rpy="0.0 -0.0 0.0" xyz="0.0 0.0 0.0"/>
      <geometry>
        <mesh filename="package://swarmfarm/meshes/swarmfarmv2_wheel_body.dae"/>
      </geometry>
    </collision>
    <inertial>
      <mass value="0.0"/>
      <origin rpy="0.0 -0.0 0.0" xyz="0.0 0.0 0.0"/>
      <inertia ixx="0.0" ixy="0.0" ixz="0.0" iyy="0.0" iyz="0.0" izz="0.0"/>
    </inertial>
  </link>
  <link name="back_left_wheel_link">
    <visual>
      <!--wheel_part/Body002.-->
      <origin rpy="0.0 -0.0 0.0" xyz="0.0 0.0 0.0"/>
      <geometry>
        <mesh filename="package://swarmfarm/meshes/swarmfarmv2_wheel_body.dae"/>
      </geometry>
    </visual>
    <collision>
      <!--wheel_part/Body002.-->
      <origin rpy="0.0 -0.0 0.0" xyz="0.0 0.0 0.0"/>
      <geometry>
        <mesh filename="package://swarmfarm/meshes/swarmfarmv2_wheel_body.dae"/>
      </geometry>
    </collision>
    <inertial>
      <mass value="0.0"/>
      <origin rpy="0.0 -0.0 0.0" xyz="0.0 0.0 0.0"/>
      <inertia ixx="0.0" ixy="0.0" ixz="0.0" iyy="0.0" iyz="0.0" izz="0.0"/>
    </inertial>
  </link>
  <joint name="chassis_joint" type="revolute">
    <parent link="front_chassis_link"/>
    <child link="back_chassis_link"/>
    <origin rpy="0.0 -0.0 0.0" xyz="-1.2 0.0 0.0"/>
    <axis xyz="0 0 1"/>
    <limit effort="10.0" lower="-0.7" upper="+0.7" velocity="10.0"/>
  </joint>
  <joint name="fright_right_wheel_joint" type="continuous">
    <parent link="front_chassis_link"/>
    <child link="front_right_wheel_link"/>
    <origin rpy="0.0 -0.0 0.0" xyz="-0.3 -0.5 0.0"/>
    <axis xyz="0 1 0"/>
  </joint>
  <joint name="back_right_wheel_joint" type="continuous">
    <parent link="back_chassis_link"/>
    <child link="back_right_wheel_link"/>
    <origin rpy="0.0 -0.0 0.0" xyz="-1.0 -0.5 0.0"/>
    <axis xyz="0 1 0"/>
  </joint>
  <joint name="back_left_wheel_joint" type="continuous">
    <parent link="back_chassis_link"/>
    <child link="back_left_wheel_link"/>
    <origin rpy="0.0 -0.0 0.0" xyz="-1.0 0.5 0.0"/>
    <axis xyz="0 1 0"/>
  </joint>
  <joint name="front_left_wheel_joint" type="continuous">
    <parent link="front_chassis_link"/>
    <child link="front_left_wheel_link"/>
    <origin rpy="0.0 -0.0 0.0" xyz="-0.3 0.5 0.0"/>
    <axis xyz="0 1 0"/>
    <limit effort="0.0" lower="0.0" upper="0.0" velocity="0.0"/>
  </joint>
</robot>
